Workbook

Sheet Masters
A1: Materials | B1: GSM/Micron | C1: Suppliers
A2: Chromo | B2: 80 | C2: Avery
A3: Chromo | B3: 80 | C3: Allied
A4: Chromo | B4: 80 | C4: Papier
A5: Chromo | B5: 80 | C5: Surya
A6: Chromo | B6: 80 | C6: Raflatech
A7: Chromo | B7: 80 | C7: Zalak
A8: Chromo | B8: 80 | C8: V - TECH
A9: Chromo | B9: 80 | C9: Tackify
A10: Chromo | B10: 80 | C10: UPM
A11: ONLY CHROMO ( GLOSS PAPER ) RAHAT HD | B11: 120 | C11: MPS Industries
A12: IML Blow Mould | B12: 70 | C12: Arjobex Polyart
A13: OPAQUE MATTE | B13: 125 | C13: Technova
... A48: Paper- AMA5050 ( PIGGYBACK) | B48: 230 | C48: Avery
A49: SILVER PAPER | C49: Mudra Arts
A50: Special SDV Grade Security Film | C50: Presen Bontek Private Limited - NEW
A51: Self Adhesive Film | B51: 80 | C51: Surya
A52: Paper - Chromo TRP1 | B52: 80 | C52: Avery

Sheet Stock In
A1: Date | B1: Supplier | C1: Material | D1: GSM/Micron | E1: Web Size (mm) | F1: RMT In | G1: Rate per Sq. Mtr | H1: Sq. Mtr In | I1: Value In | J1: Column 1
A2: 21-08-2025 | B2: Avery | C2: Chromo | D2: 80 | E2: 125 | F2: 13750 | G2: 29 | H2: =(E2*F2)/1000 -> 1718.75 | I2: =H2*G2 -> 49843.75
A3: 21-08-2025 | B3: Avery | C3: Chromo | D3: 80 | E3: 140 | F3: 300 | G3: 29 | H3: =(E3*F3)/1000 -> 42 | I3: =H3*G3 -> 1218
A4: 21-08-2025 | B4: Avery | C4: Chromo | D4: 80 | E4: 150 | F4: 6000 | G4: 29 | H4: =(E4*F4)/1000 -> 900 | I4: =H4*G4 -> 26100
A5: 21-08-2025 | B5: Avery | C5: Chromo | D5: 80 | E5: 160 | F5: 6450 | G5: 29 | H5: =(E5*F5)/1000 -> 1032 | I5: =H5*G5 -> 29928
A6: 21-08-2025 | B6: Avery | C6: Chromo | D6: 80 | E6: 170 | F6: 3850 | G6: 29 | H6: =(E6*F6)/1000 -> 654.5 | I6: =H6*G6 -> 18980.5
A7: 21-08-2025 | B7: Avery | C7: Chromo | D7: 60 | E7: 170 | F7: 2200 | G7: 29 | H7: =(E7*F7)/1000 -> 374 | I7: =H7*G7 -> 10846
A8: 21-08-2025 | B8: Avery | C8: Chromo | D8: 80 | E8: 180 | F8: 9700 | G8: 29 | H8: =(E8*F8)/1000 -> 1746 | I8: =H8*G8 -> 50634
A9: 21-08-2025 | B9: Avery | C9: Chromo | D9: 80 | E9: 190 | F9: 3400 | G9: 29 | H9: =(E9*F9)/1000 -> 646 | I9: =H9*G9 -> 18734
A10: 21-08-2025 | B10: Avery | C10: Chromo | D10: 80 | E10: 210 | F10: 7300 | G10: 29 | H10: =(E10*F10)/1000 -> 1533 | I10: =H10*G10 -> 44457
A11: 21-08-2025 | B11: Avery | C11: Chromo | D11: 80 | E11: 250 | F11: 10650 | G11: 29 | H11: =(E11*F11)/1000 -> 2662.5 | I11: =H11*G11 -> 77212.5
A12: 21-08-2025 | B12: Avery | C12: Chromo | D12: 80 | E12: 280 | F12: 11400 | G12: 29 | H12: =(E12*F12)/1000 -> 3192 | I12: =H12*G12 -> 92568
A13: 21-08-2025 | B13: Avery | C13: Chromo | D13: 80 | E13: 290 | F13: 24800 | G13: 29 | H13: =(E13*F13)/1000 -> 7192 | I13: =H13*G13 -> 208568
... A75: 21-08-2025 | B75: UPM | C75: PP WHITE | D75: 50 | E75: 265 | F75: 1000 | G75: 35 | H75: =(E75*F75)/1000 -> 265 | I75: =H75*G75 -> 9275
A76: 21-08-2025 | B76: MPS Industries | C76: ONLY CHROMO ( GLOSS PAPER ) RAHAT HD | D76: 120 | E76: 250 | F76: 6000 | H76: =(E76*F76)/1000 -> 1500 | I76: =H76*G76 -> 0
A77: 21-08-2025 | B77: Arjobex Polyart | C77: IML Blow Mould | D77: 70 | E77: 210 | F77: 2700 | G77: 48 | H77: =(E77*F77)/1000 -> 567 | I77: =H77*G77 -> 27216
A78: 21-08-2025 | B78: Arjobex Polyart | C78: IML Blow Mould | D78: 70 | E78: 200 | F78: 1950 | G78: 48 | H78: =(E78*F78)/1000 -> 390 | I78: =H78*G78 -> 18720
A79: 21-08-2025 | B79: Arjobex Polyart | C79: IML Blow Mould | D79: 70 | E79: 380 | F79: 2000 | G79: 48 | H79: =(E79*F79)/1000 -> 760 | I79: =H79*G79 -> 36480
A80: 21-08-2025 | B80: Papier | C80: Void | D80: 50 | E80: 205 | F80: 900 | G80: 165 | H80: =(E80*F80)/1000 -> 184.5 | I80: =H80*G80 -> 30442.5
A81: 21-08-2025 | B81: Technova | C81: PET MATT | D81: 125 | E81: 180 | F81: 500 | G81: 47 | H81: =(E81*F81)/1000 -> 90 | I81: =H81*G81 -> 4230
A82: 21-08-2025 | B82: Technova | C82: PET MATT | D82: 125 | E82: 220 | F82: 1200 | G82: 47 | H82: =(E82*F82)/1000 -> 264 | I82: =H82*G82 -> 12408
A83: 21-08-2025 | B83: DEE DEE LABEL | C83: U- CHROMO 80/60 WGL (HM) | D83: 80 | E83: 334 | F83: 1856 | G83: 25.5 | H83: =(E83*F83)/1000 -> 619.904 | I83: =H83*G83 -> 15807.552
A84: 21-08-2025 | B84: Papier | C84: Void | D84: 50 | E84: 125 | F84: 3920 | G84: 165 | H84: =(E84*F84)/1000 -> 490 | I84: =H84*G84 -> 80850
A85: 21-08-2025 | B85: Papier | C85: Void | D85: 50 | E85: 165 | F85: 500 | G85: 165 | H85: =(E85*F85)/1000 -> 82.5 | I85: =H85*G85 -> 13612.5
A86: 25-08-2025 | B86: Verifys | C86: SGL Hologram | D86: 23 | E86: 13 | F86: 1530 | G86: 226 | H86: =(E86*F86)/1000 -> 19.89 | I86: =H86*G86 -> 4495.14
A87: 25-08-2025 | B87: Verifys | C87: SGL Hologram | D87: 23 | E87: 20 | F87: 920 | G87: 280 | H87: =(E87*F87)/1000 -> 18.4 | I87: =H87*G87 -> 5152
A88: 28-08-2025 | B88: Sonafine Corporation Pvt Ltd | C88: Blochum Blue Paper Sheet | D88: 250 | E88: 0 | F88: 0 | G88: 41.33 | H88: =(E88*F88)/1000 -> 0 | I88: =H88*G88 -> 0
... A93: 30-08-2025 | B93: Avery | C93: PP WHITE | D93: 50 | E93: 160 | F93: 4000 | G93: 37 | H93: =(E93*F93)/1000 -> 640 | I93: =H93*G93 -> 23680
A94: 45725 | B94: Avery | C94: Chromo | D94: 80 | E94: 230 | F94: 24000 | G94: 28.5 | H94: =(E94*F94)/1000 -> 5520 | I94: =H94*G94 -> 157320
A95: 45756 | B95: Avery | C95: PP WHITE | D95: 50 | E95: 100 | F95: 3980 | G95: 37 | H95: =(E95*F95)/1000 -> 398 | I95: =H95*G95 -> 14726
A96: 45786 | B96: Surya | C96: Chromo | D96: 80 | E96: 140 | F96: 9380 | G96: 26.5 | H96: =(E96*F96)/1000 -> 1313.2 | I96: =H96*G96 -> 34799.8
A97: 45786 | B97: Surya | C97: Chromo | D97: 80 | E97: 160 | F97: 18380 | G97: 26.5 | H97: =(E97*F97)/1000 -> 2940.8 | I97: =H97*G97 -> 77931.2
A98: 45786 | B98: Surya | C98: Chromo | D98: 80 | E98: 185 | F98: 6390 | G98: 26.5 | H98: =(E98*F98)/1000 -> 1182.15 | I98: =H98*G98 -> 31326.975
A99: 45786 | B99: Surya | C99: Chromo | D99: 80 | E99: 230 | F99: 6000 | G99: 26.5 | H99: =(E99*F99)/1000 -> 1380 | I99: =H99*G99 -> 36570
A100: 45786 | B100: Surya | C100: SILVER PAPER | D100: 80 | E100: 140 | F100: 3030 | G100: 43.85 | H100: =(E100*F100)/1000 -> 424.2 | I100: =H100*G100 -> 18601.17
A101: 45786 | B101: Surya | C101: SILVER PAPER | D101: 80 | E101: 280 | F101: 3030 | G101: 43.85 | H101: =(E101*F101)/1000 -> 848.4 | I101: =H101*G101 -> 37202.34
A102: 45786 | B102: Stick Tapes | C102: Tape | D102: 12 | E102: 72 | F102: 6000 | G102: 230 | H102: =(E102*F102)/1000 -> 432 | I102: =H102*G102 -> 99360
A103: 16-09-2025 | B103: Avery | C103: Chromo | D103: 80 | E103: 125 | F103: 10000 | G103: 28.5 | H103: =(E103*F103)/1000 -> 1250 | I103: =H103*G103 -> 35625
A104: 17-09-2025 | B104: Surya | C104: PP WHITE | D104: 50 | E104: 125 | F104: 1070 | G104: 34 | H104: =(E104*F104)/1000 -> 133.75 | I104: =H104*G104 -> 4547.5
A105: 17-09-2025 | B105: Surya | C105: PP WHITE | D105: 50 | E105: 190 | F105: 2140 | G105: 36 | H105: =(E105*F105)/1000 -> 406.6 | I105: =H105*G105 -> 14637.6
...

Sheet Issues
A1: Date | B1: Job No. | C1: Material | D1: GSM/Micron | E1: Web Size (mm) | F1: Supplier | G1: Client | H1: RMT Issued | I1: Sq. Mtr Issued | J1: Remarks | K1: Column 1
A2: 45891 | B2: 08/061 | C2: SILVER PAPER | D2: 80 | E2: 280 | F2: Surya | G2: KONARK PROPACK | H2: 400 | I2: =H2*E2/1000 -> 112
A3: 45891 | B3: 08/061 | C3: SILVER PAPER | D3: 80 | E3: 260 | F3: Surya | G3: KONARK PROPACK | H3: 1000 | I3: =H3*E3/1000 -> 260
A4: 45891 | B4: 08/061 | C4: SILVER PAPER | D4: 80 | E4: 160 | F4: Surya | G4: KONARK PROPACK | H4: 540 | I4: =H4*E4/1000 -> 86.4
A5: 45891 | B5: 08/061 | C5: SILVER PAPER | D5: 80 | E5: 140 | F5: Surya | G5: KONARK PROPACK | H5: 1350 | I5: =H5*E5/1000 -> 189
A6: 45891 | B6: 08/064 | C6: Chromo | D6: 80 | E6: 125 | F6: Avery | G6: Rallis | H6: 1724 | I6: =H6*E6/1000 -> 215.5
A7: 45891 | B7: 08/065 | C7: Chromo | D7: 80 | E7: 330 | F7: Avery | G7: Rallis | H7: 1700 | I7: =H7*E7/1000 -> 561
A8: 45891 | B8: 08/067 | C8: Chromo | D8: 80 | E8: 330 | F8: Avery | G8: Rallis | H8: 3150 | I8: =H8*E8/1000 -> 1039.5
A9: 45891 | B9: 08/068 | C9: Chromo | D9: 80 | E9: 125 | F9: Avery | G9: Rallis | H9: 1370 | I9: =H9*E9/1000 -> 171.25
A10: 45891 | B10: 08/074 | C10: Chromo | D10: 80 | E10: 290 | F10: Avery | G10: Rallis | H10: 1000 | I10: =H10*E10/1000 -> 290
A11: 45891 | B11: 08/096 | C11: Chromo | D11: 80 | E11: 125 | F11: Avery | G11: Rallis | H11: 2684 | I11: =H11*E11/1000 -> 335.5
A12: 45892 | B12: 08/040 | C12: Void | D12: 50 | E12: 165 | F12: Papier | G12: sgl | H12: 350 | I12: =H12*E12/1000 -> 57.75
A13: 45892 | B13: 08/040 | C13: Void | D13: 50 | E13: 125 | F13: Papier | G13: sgl | H13: 1000 | I13: =H13*E13/1000 -> 125
... A132: 45923 | B132: 09/101 | C132: SILVER PAPER | D132: 80 | E132: 167 | F132: Surya | G132: OXITECH | H132: 7500 | I132: =H132*E132/1000 -> 1252.5
A133: 45923 | B133: 09/102 | C133: SILVER PAPER | D133: 80 | E133: 280 | F133: Surya | G133: OXITECH | H133: 3000 | I133: =H133*E133/1000 -> 840 | J133: 280 SIZE CENTER CUT BY 140
A134: 45923 | B134: 09/103 | C134: PP WHITE | D134: 50 | E134: 125 | F134: Surya | G134: HERBAL HILL | H134: 2010 | I134: =H134*E134/1000 -> 251.25
A135: 45923 | B135: 09/118 | C135: Chromo | D135: 80 | E135: 125 | F135: Avery | G135: RALLIS | H135: 2300 | I135: =H135*E135/1000 -> 287.5
A136: 45923 | B136: 09/083 | C136: Chromo | D136: 80 | E136: 250 | F136: Avery | G136: RALLIS | H136: 2000 | I136: =H136*E136/1000 -> 500
A137: 45924 | B137: 09/058 | C137: Chromo | D137: 80 | E137: 230 | F137: Surya | G137: GLOBAL | H137: 950 | I137: =H137*E137/1000 -> 218.5
A138: 45924 | B138: 09/058 | C138: Chromo | D138: 80 | E138: 240 | F138: Surya | G138: GLOBAL | H138: 400 | I138: =H138*E138/1000 -> 96
A139: 45924 | B139: 09/072 | C139: Chromo | D139: 80 | E139: 160 | F139: Surya | G139: GLOBAL | H139: 1700 | I139: =H139*E139/1000 -> 272
A140: 45924 | B140: 09/100 | C140: SILVER PAPER | D140: 80 | E140: 280 | F140: Surya | G140: OXITECH | H140: 920 | I140: =H140*E140/1000 -> 257.6
A141: 45924 | B141: 09/119 | C141: Chromo | D141: 80 | E141: 160 | F141: Surya | G141: ARIES | H141: 6200 | I141: =H141*E141/1000 -> 992
A142: 45924 | B142: 09/127 | C142: Chromo | D142: 80 | E142: 160 | F142: Surya | G142: ARIES | H142: 3500 | I142: =H142*E142/1000 -> 560
A143: 45924 | B143: 09/128 | C143: Chromo | D143: 80 | E143: 140 | F143: Surya | G143: ARIES | H143: 3100 | I143: =H143*E143/1000 -> 434
A144: 45925 | B144: 09/108 | C144: Chromo | D144: 80 | E144: 195 | F144: Surya | G144: PURE IMPRESSION | H144: 2070 | I144: =H144*E144/1000 -> 403.65
A145: 45925 | B145: 09/109 | C145: Chromo | D145: 80 | E145: 185 | F145: Surya | G145: PURE IMPRESSION | H145: 1250 | I145: =H145*E145/1000 -> 231.25
... A151: 45926 | B151: 09/133 | C151: PP CLEAR | D151: 80 | E151: 255 | F151: V - TECH | G151: ANU IND | H151: 1710 | I151: =H151*E151/1000 -> 436.05
A152: 45926 | B152: 09/135 | E152: 250 | G152: PROPIX | H152: 173 | I152: =H152*E152/1000 -> 43.25 | J152: SAMPLE
A153: 45927 | B153: 09/132 | C153: Chromo | D153: 80 | E153: 125 | F153: Avery | G153: RALLIS | H153: 1000 | I153: =H153*E153/1000 -> 125
A154: 45927 | B154: 09/121 | C154: PP WHITE | D154: 50 | E154: 190 | F154: Avery | G154: ARIES | H154: 700 | I154: =H154*E154/1000 -> 133
A155: 45927 | B155: 09/124 | C155: PP WHITE | D155: 50 | E155: 300 | F155: Surya | G155: ARIES | H155: 650 | I155: =H155*E155/1000 -> 195
A156: 45929 | B156: 09/126 | C156: Chromo | D156: 80 | E156: 126 | F156: Surya | G156: GLOBAL | H156: 500 | I156: =H156*E156/1000 -> 63
A157: 45929 | B157: 09/141 | C157: Chromo | D157: 80 | E157: 290 | F157: Avery | G157: RALLIS | H157: 2000 | I157: =H157*E157/1000 -> 580
A158: 45929 | B158: 09/143 | C158: Chromo | D158: 80 | E158: 210 | F158: Avery | G158: RALLIS | H158: 2000 | I158: =H158*E158/1000 -> 420
A159: 45929 | B159: 09/144 | C159: Chromo | D159: 80 | E159: 290 | F159: Avery | G159: RALLIS | H159: 2600 | I159: =H159*E159/1000 -> 754
A160: 45929 | B160: 09/145 | C160: Chromo | D160: 80 | E160: 320 | F160: Avery | G160: RALLIS | H160: 1050 | I160: =H160*E160/1000 -> 336
A161: 45929 | B161: 09/146 | C161: Chromo | D161: 80 | E161: 290 | F161: Avery | G161: RALLIS | H161: 1450 | I161: =H161*E161/1000 -> 420.5
A162: 45930 | B162: 09/125 | C162: Chromo | D162: 80 | E162: 185 | F162: Surya | G162: global | H162: 1100 | I162: =H162*E162/1000 -> 203.5
A163: 45930 | B163: 09/129 | C163: Chromo | D163: 80 | E163: 126 | F163: Surya | G163: global | H163: 1300 | I163: =H163*E163/1000 -> 163.8
...

Sheet Returns
A1: Date | B1: Job No. | C1: Material | D1: GSM/Micron | E1: Web Size (mm) | F1: Supplier | G1: Client | H1: RMT Returned | I1: Column 11 | J1: Sq. Mtr Returned | K1: Remarks | L1: Column 1
A2: 45891 | B2: 08/061 | C2: SILVER PAPER | D2: 80 | E2: 280 | F2: Surya | G2: KONARK PROPACK | H2: 0 | J2: =(E2*H2)/1000 -> 0
A3: 45891 | B3: 08/061 | C3: SILVER PAPER | D3: 80 | E3: 260 | F3: Surya | G3: KONARK PROPACK | H3: 0 | J3: =(E3*H3)/1000 -> 0
A4: 45891 | B4: 08/061 | C4: SILVER PAPER | D4: 80 | E4: 160 | F4: Surya | G4: KONARK PROPACK | H4: 0 | J4: =(E4*H4)/1000 -> 0
A5: 45891 | B5: 08/061 | C5: SILVER PAPER | D5: 80 | E5: 140 | F5: Surya | G5: KONARK PROPACK | H5: 0 | J5: =(E5*H5)/1000 -> 0
A6: 45891 | B6: 08/064 | C6: Chromo | D6: 80 | E6: 125 | F6: Avery | G6: Rallis | H6: 1015 | J6: =(E6*H6)/1000 -> 126.875
A7: 45891 | B7: 08/065 | C7: Chromo | D7: 80 | E7: 330 | F7: Avery | G7: Rallis | H7: 1090 | J7: =(E7*H7)/1000 -> 359.7
A8: 45891 | B8: 08/067 | C8: Chromo | D8: 80 | E8: 330 | F8: Avery | G8: Rallis | H8: 1730 | J8: =(E8*H8)/1000 -> 570.9
A9: 45891 | B9: 08/068 | C9: Chromo | D9: 80 | E9: 125 | F9: Avery | G9: Rallis | H9: 684 | J9: =(E9*H9)/1000 -> 85.5
A10: 45891 | B10: 08/074 | C10: Chromo | D10: 80 | E10: 290 | F10: Avery | G10: Rallis | H10: 0 | J10: =(E10*H10)/1000 -> 0
A11: 45891 | B11: 08/096 | C11: Chromo | D11: 80 | E11: 125 | F11: Avery | G11: Rallis | H11: 1724 | J11: =(E11*H11)/1000 -> 215.5
A12: 45892 | B12: 08/040 | C12: Void | D12: 50 | E12: 165 | F12: Papier | G12: sgl | H12: 0 | J12: =(E12*H12)/1000 -> 0
A13: 45892 | B13: 08/040 | C13: Void | D13: 50 | E13: 125 | F13: Papier | G13: sgl | H13: 0 | J13: =(E13*H13)/1000 -> 0
... A56: 45909 | B56: 09/010 | C56: SILVER PAPER | D56: 80 | E56: 140 | F56: Surya | G56: SUDARSHAN PHARMA | H56: 734 | J56: =(E56*H56)/1000 -> 102.76
A57: 45909 | B57: 09/019 | C57: Chromo | D57: 80 | E57: 140 | F57: Surya | G57: ARIES | J57: =(E57*H57)/1000 -> 0 | K57: NO RETURN
A58: 45909 | B58: 09/034 | C58: Chromo | D58: 80 | E58: 126 | F58: Surya | G58: GLOBAL | H58: 350 | J58: =(E58*H58)/1000 -> 44.1
A59: 45909 | B59: 09/042 | C59: Chromo | D59: 80 | E59: 160 | F59: Surya | G59: ARIES | H59: 600 | J59: =(E59*H59)/1000 -> 96
A60: 45909 | B60: 09/044 | C60: Chromo | D60: 80 | E60: 140 | F60: Surya | G60: ARIES | H60: 500 | J60: =(E60*H60)/1000 -> 70
A61: 45909 | B61: 09/045 | C61: Chromo | D61: 80 | E61: 140 | F61: Surya | G61: ARIES | H61: 1360 | J61: =(E61*H61)/1000 -> 190.4
A62: 45910 | B62: 07/181 | C62: PP WHITE | E62: 167 | F62: Allied | G62: ARIES | H62: 1350 | J62: =(E62*H62)/1000 -> 225.45
A63: 45910 | B63: 09/038 | C63: Chromo | D63: 80 | E63: 320 | F63: Avery | G63: RALLIS | J63: =(E63*H63)/1000 -> 0 | K63: NO RETURN
A64: 45910 | B64: 09/039 | C64: Chromo | D64: 80 | E64: 125 | F64: Avery | G64: RALLIS | H64: 700 | J64: =(E64*H64)/1000 -> 87.5
A65: 45910 | B65: 09/061 | C65: Chromo | D65: 80 | E65: 190 | F65: Avery | G65: PREGNA | H65: 300 | J65: =(E65*H65)/1000 -> 57
A66: 45911 | B66: 08/135 | C66: Chromo | D66: 80 | E66: 160 | F66: Surya | G66: ARIES | H66: 200 | J66: =(E66*H66)/1000 -> 32
A67: 45911 | B67: 09/035 | C67: Chromo | D67: 80 | E67: 160 | F67: Surya | G67: ARIES | H67: 500 | J67: =(E67*H67)/1000 -> 80
A68: 45911 | B68: 09/040 | C68: Chromo | D68: 80 | E68: 160 | F68: Surya | G68: ARIES | J68: =(E68*H68)/1000 -> 0 | K68: NO RETURN
A69: 45911 | B69: 09/065 | C69: Chromo | D69: 80 | E69: 140 | F69: Surya | G69: ARIES | H69: 380 | J69: =(E69*H69)/1000 -> 53.2
A70: 45912 | B70: 09/048 | C70: Chromo | D70: 80 | E70: 230 | F70: Surya | G70: ARIES | H70: 450 | J70: =(E70*H70)/1000 -> 103.5
A71: 45912 | B71: 09/053 | C71: Chromo | D71: 80 | E71: 230 | F71: Surya | G71: ARIES | H71: 1300 | J71: =(E71*H71)/1000 -> 299
A72: 45912 | B72: 09/054 | C72: Chromo | D72: 80 | E72: 230 | F72: Surya | G72: ARIES | H72: 700 | J72: =(E72*H72)/1000 -> 161
A73: 45912 | B73: 09/055 | C73: Chromo | D73: 80 | E73: 210 | F73: Surya | G73: ARIES | H73: 0 | J73: =(E73*H73)/1000 -> 0 | K73: NO RETURN
A74: 45912 | B74: 09/055 | C74: Chromo | D74: 80 | E74: 195 | F74: Surya | G74: ARIES | H74: 0 | J74: =(E74*H74)/1000 -> 0
A75: 45912 | B75: 09/055 | C75: Chromo | D75: 80 | E75: 200 | F75: Surya | G75: ARIES | H75: 0 | J75: =(E75*H75)/1000 -> 0
A76: 45912 | B76: 09/059 | C76: Chromo | D76: 80 | E76: 126 | F76: Surya | G76: ARIES | H76: 580 | J76: =(E76*H76)/1000 -> 73.08
A77: 45912 | B77: 09/060 | C77: Chromo | D77: 80 | E77: 140 | F77: Surya | G77: ARIES | H77: 0 | J77: =(E77*H77)/1000 -> 0
A78: 45912 | B78: 09/066 | C78: Chromo | D78: 80 | E78: 140 | F78: Surya | G78: ARIES | H78: 1360 | J78: =(E78*H78)/1000 -> 190.4
A79: 45912 | B79: 09/067 | C79: Chromo | D79: 80 | E79: 230 | F79: Surya | G79: ARIES | H79: 100 | J79: =(E79*H79)/1000 -> 23
A80: 45912 | B80: 09/074 | C80: Chromo | D80: 80 | E80: 230 | F80: Surya | G80: ARIES | H80: 280 | J80: =(E80*H80)/1000 -> 64.4
A81: 45912 | B81: 09/075 | C81: Chromo | D81: 80 | E81: 230 | F81: Surya | G81: ARIES | H81: 900 | J81: =(E81*H81)/1000 -> 207
A82: 45913 | B82: 09/041 | C82: Chromo | D82: 80 | E82: 260 | F82: Surya | G82: ARIES | H82: 150 | J82: =(E82*H82)/1000 -> 39
...

Sheet Job usage
A1: Column 1 | B1: Material | C1: GSM/Micron | D1: Web Size (mm) | E1: Target RMT | F1: Job Run RMT | G1: RMT Issued | H1: RMT Returned | I1: Ok Quantity | J1: Total Ups | K1: Cylinder Size | L1: Ok Quantity RMT | M1: RMT Used | N1: Wastage RMT | O1: Wastage Sq. Mtr
A2: 08/061 | B2: SILVER PAPER | C2: 80 | D2: 280 | E2: 2624 | F2: 3290 | G2: =IFERROR(SUMIF(Issues!B:B, A2, Issues!H:H), 0) -> 3290 | H2: =IFERROR(SUMIF(Returns!B:B, A2, Returns!H:H), 0) -> 0 | I2: 132720 | J2: 15 | K2: 99 | L2: =IFERROR((I2*(K2/8))/(39.3*J2),0) -> 2786.1069 | M2: =G2 - H2 -> 3290 | N2: =MAX(0, G2-H2-L2) -> 503.89313 | O2: =(D2*N2)/1000 -> 141.09008
A3: 08/064 | B3: Chromo | C3: 80 | D3: 125 | E3: 515 | F3: 709 | G3: =IFERROR(SUMIF(Issues!B:B, A3, Issues!H:H), 0) -> 1724 | H3: =IFERROR(SUMIF(Returns!B:B, A3, Returns!H:H), 0) -> 1015 | I3: 3490 | J3: 2 | K3: 108 | L3: =IFERROR((I3*(K3/8))/(39.3*J3),0) -> 599.42748 | M3: =G3 - H3 -> 709 | N3: =MAX(0, G3-H3-L3) -> 109.57252 | O3: =(D3*N3)/1000 -> 13.696565
A4: 08/065 | B4: Chromo | C4: 80 | D4: 330 | E4: 398 | F4: 606 | G4: =IFERROR(SUMIF(Issues!B:B, A4, Issues!H:H), 0) -> 1700 | H4: =IFERROR(SUMIF(Returns!B:B, A4, Returns!H:H), 0) -> 1090 | I4: 5640 | J4: 3 | K4: 75 | L4: =IFERROR((I4*(K4/8))/(39.3*J4),0) -> 448.47328 | M4: =G4 - H4 -> 610 | N4: =MAX(0, G4-H4-L4) -> 161.52672 | O4: =(D4*N4)/1000 -> 53.303817
A5: 08/067 | B5: Chromo | C5: 80 | D5: 330 | E5: 1193 | F5: 1420 | G5: =IFERROR(SUMIF(Issues!B:B, A5, Issues!H:H), 0) -> 3150 | H5: =IFERROR(SUMIF(Returns!B:B, A5, Returns!H:H), 0) -> 1730 | I5: 15000 | J5: 3 | K5: 75 | L5: =IFERROR((I5*(K5/8))/(39.3*J5),0) -> 1192.7481 | M5: =G5 - H5 -> 1420 | N5: =MAX(0, G5-H5-L5) -> 227.25191 | O5: =(D5*N5)/1000 -> 74.99313
A6: 08/068 | B6: Chromo | C6: 80 | D6: 125 | E6: 515 | F6: 686 | G6: =IFERROR(SUMIF(Issues!B:B, A6, Issues!H:H), 0) -> 1370 | H6: =IFERROR(SUMIF(Returns!B:B, A6, Returns!H:H), 0) -> 684 | I6: 3280 | J6: 2 | K6: 108 | L6: =IFERROR((I6*(K6/8))/(39.3*J6),0) -> 563.35878 | M6: =G6 - H6 -> 686 | N6: =MAX(0, G6-H6-L6) -> 122.64122 | O6: =(D6*N6)/1000 -> 15.330153
A7: 08/074 | B7: Chromo | C7: 80 | D7: 290 | E7: 747 | F7: 930 | G7: =IFERROR(SUMIF(Issues!B:B, A7, Issues!H:H), 0) -> 1000 | H7: =IFERROR(SUMIF(Returns!B:B, A7, Returns!H:H), 0) -> 0 | I7: 5200 | J7: 2 | K7: 94 | L7: =IFERROR((I7*(K7/8))/(39.3*J7),0) -> 777.35369 | M7: =G7 - H7 -> 1000 | N7: =MAX(0, G7-H7-L7) -> 222.64631 | O7: =(D7*N7)/1000 -> 64.56743
A8: 08/096 | B8: Chromo | C8: 80 | D8: 125 | E8: 687 | F8: 960 | G8: =IFERROR(SUMIF(Issues!B:B, A8, Issues!H:H), 0) -> 2684 | H8: =IFERROR(SUMIF(Returns!B:B, A8, Returns!H:H), 0) -> 1724 | I8: 4450 | J8: 2 | K8: 108 | L8: =IFERROR((I8*(K8/8))/(39.3*J8),0) -> 764.31298 | M8: =G8 - H8 -> 960 | N8: =MAX(0, G8-H8-L8) -> 195.68702 | O8: =(D8*N8)/1000 -> 24.460878
A9: 08/040 | B9: Void | C9: 50 | D9: 165 | E9: 657 | F9: 1161 | G9: =IFERROR(SUMIF(Issues!B:B, A9, Issues!H:H), 0) -> 1350 | H9: =IFERROR(SUMIF(Returns!B:B, A9, Returns!H:H), 0) -> 0 | I9: 65300 | J9: 30 | K9: 124 | L9: =IFERROR((I9*(K9/8))/(39.3*J9),0) -> 858.48176 | M9: =G9 - H9 -> 1350 | N9: =MAX(0, G9-H9-L9) -> 491.51824 | O9: =(D9*N9)/1000 -> 81.100509
A10: 08/087 | B10: Chromo | C10: 80 | D10: 160 | E10: 429 | F10: 697 | G10: =IFERROR(SUMIF(Issues!B:B, A10, Issues!H:H), 0) -> 900 | H10: =IFERROR(SUMIF(Returns!B:B, A10, Returns!H:H), 0) -> 203 | I10: 12720 | J10: 8 | K10: 108 | L10: =IFERROR((I10*(K10/8))/(39.3*J10),0) -> 546.18321 | M10: =G10 - H10 -> 697 | N10: =MAX(0, G10-H10-L10) -> 150.81679 | O10: =(D10*N10)/1000 -> 24.130687
A11: 08/095 | B11: Chromo | C11: 80 | D11: 125 | E11: 515 | F11: 724 | G11: =IFERROR(SUMIF(Issues!B:B, A11, Issues!H:H), 0) -> 1015 | H11: =IFERROR(SUMIF(Returns!B:B, A11, Returns!H:H), 0) -> 290 | I11: 3150 | J11: 2 | K11: 108 | L11: =IFERROR((I11*(K11/8))/(39.3*J11),0) -> 541.03053 | M11: =G11 - H11 -> 725 | N11: =MAX(0, G11-H11-L11) -> 183.96947 | O11: =(D11*N11)/1000 -> 22.996183
A12: 08/104 | B12: Chromo | C12: 80 | D12: 125 | E12: 687 | F12: 955 | G12: =IFERROR(SUMIF(Issues!B:B, A12, Issues!H:H), 0) -> 2040 | H12: =IFERROR(SUMIF(Returns!B:B, A12, Returns!H:H), 0) -> 1440 | I12: 4500 | J12: 2 | K12: 108 | L12: =IFERROR((I12*(K12/8))/(39.3*J12),0) -> 772.90076 | M12: =G12 - H12 -> 600 | N12: =MAX(0, G12-H12-L12) -> 0 | O12: =(D12*N12)/1000 -> 0
A13: 08/108 | B13: Chromo | C13: 80 | D13: 125 | E13: 120 | F13: 259 | G13: =IFERROR(SUMIF(Issues!B:B, A13, Issues!H:H), 0) -> 1440 | H13: =IFERROR(SUMIF(Returns!B:B, A13, Returns!H:H), 0) -> 1180 | I13: 700 | J13: 2 | K13: 108 | L13: =IFERROR((I13*(K13/8))/(39.3*J13),0) -> 120.22901 | M13: =G13 - H13 -> 260 | N13: =MAX(0, G13-H13-L13) -> 139.77099 | O13: =(D13*N13)/1000 -> 17.471374
... A50: 09/019 | B50: Chromo | C50: 80 | D50: 140 | E50: 2634 | F50: 2920 | G50: =IFERROR(SUMIF(Issues!B:B, A50, Issues!H:H), 0) -> 3000 | H50: =IFERROR(SUMIF(Returns!B:B, A50, Returns!H:H), 0) -> 0 | I50: 12187 | J50: 1 | K50: 69 | L50: =IFERROR((I50*(K50/8))/(39.3*J50),0) -> 2674.6279 | M50: =G50 - H50 -> 3000 | N50: =MAX(0, G50-H50-L50) -> 325.37214 | O50: =(D50*N50)/1000 -> 45.552099
A51: 09/034 | B51: Chromo | C51: 80 | D51: 126 | E51: 596 | F51: 891 | G51: =IFERROR(SUMIF(Issues!B:B, A51, Issues!H:H), 0) -> 1260 | H51: =IFERROR(SUMIF(Returns!B:B, A51, Returns!H:H), 0) -> 350 | I51: 5400 | L51: =IFERROR((I51*(K51/8))/(39.3*J51),0) -> 0 | M51: =G51 - H51 -> 910 | N51: =MAX(0, G51-H51-L51) -> 910 | O51: =(D51*N51)/1000 -> 114.66
A52: 09/042 | B52: Chromo | C52: 80 | D52: 160 | E52: 849 | G52: =IFERROR(SUMIF(Issues!B:B, A52, Issues!H:H), 0) -> 1720 | H52: =IFERROR(SUMIF(Returns!B:B, A52, Returns!H:H), 0) -> 600 | I52: 3305 | J52: 1 | K52: 89 | L52: =IFERROR((I52*(K52/8))/(39.3*J52),0) -> 935.5757 | M52: =G52 - H52 -> 1120 | N52: =MAX(0, G52-H52-L52) -> 184.4243 | O52: =(D52*N52)/1000 -> 29.507888
A53: 09/034 | B53: Chromo | C53: 80 | D53: 126 | E53: 596 | F53: 891 | G53: =IFERROR(SUMIF(Issues!B:B, A53, Issues!H:H), 0) -> 1260 | H53: =IFERROR(SUMIF(Returns!B:B, A53, Returns!H:H), 0) -> 350 | I53: 5400 | J53: 2 | K53: 75 | L53: =IFERROR((I53*(K53/8))/(39.3*J53),0) -> 644.08397 | M53: =G53 - H53 -> 910 | N53: =MAX(0, G53-H53-L53) -> 265.91603 | O53: =(D53*N53)/1000 -> 33.50542
A54: 09/044 | B54: Chromo | C54: 80 | D54: 140 | E54: 658 | F54: 970 | G54: =IFERROR(SUMIF(Issues!B:B, A54, Issues!H:H), 0) -> 1500 | H54: =IFERROR(SUMIF(Returns!B:B, A54, Returns!H:H), 0) -> 500 | I54: 3782 | J54: 1 | K54: 69 | L54: =IFERROR((I54*(K54/8))/(39.3*J54),0) -> 830.01908 | M54: =G54 - H54 -> 1000 | N54: =MAX(0, G54-H54-L54) -> 169.98092 | O54: =(D54*N54)/1000 -> 23.797328
A55: 09/045 | B55: Chromo | C55: 80 | D55: 140 | E55: 2195 | F55: 2489 | G55: =IFERROR(SUMIF(Issues!B:B, A55, Issues!H:H), 0) -> 3880 | H55: =IFERROR(SUMIF(Returns!B:B, A55, Returns!H:H), 0) -> 1360 | I55: 10780 | J55: 1 | K55: 69 | L55: =IFERROR((I55*(K55/8))/(39.3*J55),0) -> 2365.8397 | M55: =G55 - H55 -> 2520 | N55: =MAX(0, G55-H55-L55) -> 154.16031 | O55: =(D55*N55)/1000 -> 21.582443
A56: 07/181 | B56: PP WHITE | D56: 167 | E56: 314 | F56: 630 | G56: 2000 | H56: =IFERROR(SUMIF(Returns!B:B, A56, Returns!H:H), 0) -> 1350 | I56: 14700 | J56: 9 | K56: 89 | L56: =IFERROR((I56*(K56/8))/(39.3*J56),0) -> 462.36217 | M56: =G56 - H56 -> 650 | N56: =MAX(0, G56-H56-L56) -> 187.63783 | O56: =(D56*N56)/1000 -> 31.335517
A57: 09/038 | B57: Chromo | C57: 80 | D57: 320 | E57: 344 | F57: 489 | G57: =IFERROR(SUMIF(Issues!B:B, A57, Issues!H:H), 0) -> 530 | H57: =IFERROR(SUMIF(Returns!B:B, A57, Returns!H:H), 0) -> 0 | I57: 2200 | J57: 2 | K57: 108 | L57: =IFERROR((I57*(K57/8))/(39.3*J57),0) -> 377.8626 | M57: =G57 - H57 -> 530 | N57: =MAX(0, G57-H57-L57) -> 152.1374 | O57: =(D57*N57)/1000 -> 48.683969
A58: 09/039 | B58: Chromo | C58: 80 | D58: 125 | E58: 1718 | F58: 2015 | G58: =IFERROR(SUMIF(Issues!B:B, A58, Issues!H:H), 0) -> 2600 | H58: =IFERROR(SUMIF(Returns!B:B, A58, Returns!H:H), 0) -> 700 | I58: 10600 | J58: 3 | K58: 108 | L58: =IFERROR((I58*(K58/8))/(39.3*J58),0) -> 1213.7405 | M58: =G58 - H58 -> 1900 | N58: =MAX(0, G58-H58-L58) -> 686.25954 | O58: =(D58*N58)/1000 -> 85.782443
A59: 09/061 | B59: Chromo | C59: 80 | D59: 190 | E59: 495 | F59: 770 | G59: =IFERROR(SUMIF(Issues!B:B, A59, Issues!H:H), 0) -> 1100 | H59: =IFERROR(SUMIF(Returns!B:B, A59, Returns!H:H), 0) -> 300 | I59: 7000 | J59: 4 | K59: 89 | L59: =IFERROR((I59*(K59/8))/(39.3*J59),0) -> 495.38804 | M59: =G59 - H59 -> 800 | N59: =MAX(0, G59-H59-L59) -> 304.61196 | O59: =(D59*N59)/1000 -> 57.876272
A60: 08/135 | B60: Chromo | C60: 80 | D60: 160 | E60: 2831 | F60: 3287 | G60: =IFERROR(SUMIF(Issues!B:B, A60, Issues!H:H), 0) -> 3500 | H60: =IFERROR(SUMIF(Returns!B:B, A60, Returns!H:H), 0) -> 200 | I60: 10600 | J60: 1 | K60: 89 | L60: =IFERROR((I60*(K60/8))/(39.3*J60),0) -> 3000.6361 | M60: =G60 - H60 -> 3300 | N60: =MAX(0, G60-H60-L60) -> 299.36387 | O60: =(D60*N60)/1000 -> 47.898219
A61: 09/035 | B61: Chromo | C61: 80 | D61: 160 | E61: 5666 | F61: 6113 | G61: =IFERROR(SUMIF(Issues!B:B, A61, Issues!H:H), 0) -> 6650 | H61: =IFERROR(SUMIF(Returns!B:B, A61, Returns!H:H), 0) -> 500 | I61: 20000 | J61: 1 | K61: 89 | L61: =IFERROR((I61*(K61/8))/(39.3*J61),0) -> 5661.5776 | M61: =G61 - H61 -> 6150 | N61: =MAX(0, G61-H61-L61) -> 488.42239 | O61: =(D61*N61)/1000 -> 78.147583
A62: 09/040 | B62: Chromo | C62: 80 | D62: 160 | E62: 1415 | F62: 1756 | G62: =IFERROR(SUMIF(Issues!B:B, A62, Issues!H:H), 0) -> 1750 | H62: =IFERROR(SUMIF(Returns!B:B, A62, Returns!H:H), 0) -> 0 | I62: 5717 | J62: 1 | K62: 89 | L62: =IFERROR((I62*(K62/8))/(39.3*J62),0) -> 1618.362 | M62: =G62 - H62 -> 1750 | N62: =MAX(0, G62-H62-L62) -> 131.63804 | O62: =(D62*N62)/1000 -> 21.062087
A63: 09/065 | B63: Chromo | C63: 80 | D63: 140 | E63: 732 | F63: 917 | G63: =IFERROR(SUMIF(Issues!B:B, A63, Issues!H:H), 0) -> 1300 | H63: =IFERROR(SUMIF(Returns!B:B, A63, Returns!H:H), 0) -> 380 | I63: 10990 | J63: 4 | K63: 92 | L63: =IFERROR((I63*(K63/8))/(39.3*J63),0) -> 803.97583 | M63: =G63 - H63 -> 920 | N63: =MAX(0, G63-H63-L63) -> 116.02417 | O63: =(D63*N63)/1000 -> 16.243384
A64: 09/048 | B64: Chromo | C64: 80 | D64: 230 | E64: 657 | F64: 818 | G64: =IFERROR(SUMIF(Issues!B:B, A64, Issues!H:H), 0) -> 1300 | H64: =IFERROR(SUMIF(Returns!B:B, A64, Returns!H:H), 0) -> 450 | I64: 10390 | J64: 6 | K64: 124 | L64: =IFERROR((I64*(K64/8))/(39.3*J64),0) -> 682.97286 | M64: =G64 - H64 -> 850 | N64: =MAX(0, G64-H64-L64) -> 167.02714 | O64: =(D64*N64)/1000 -> 38.416243
A65: 09/053 | B65: Chromo | C65: 80 | D65: 230 | E65: 263 | F65: 470 | G65: =IFERROR(SUMIF(Issues!B:B, A65, Issues!H:H), 0) -> 1780 | H65: =IFERROR(SUMIF(Returns!B:B, A65, Returns!H:H), 0) -> 1300 | I65: 6060 | J65: 6 | K65: 124 | L65: =IFERROR((I65*(K65/8))/(39.3*J65),0) -> 398.34606 | M65: =G65 - H65 -> 480 | N65: =MAX(0, G65-H65-L65) -> 81.653944 | O65: =(D65*N65)/1000 -> 18.780407
A66: 09/054 | B66: Chromo | C66: 80 | D66: 230 | E66: 4126 | F66: 4400 | G66: =IFERROR(SUMIF(Issues!B:B, A66, Issues!H:H), 0) -> 5200 | H66: =IFERROR(SUMIF(Returns!B:B, A66, Returns!H:H), 0) -> 700 | I66: 29137 | J66: 2 | K66: 92 | L66: =IFERROR((I66*(K66/8))/(39.3*J66),0) -> 4263.0471 | M66: =G66 - H66 -> 4500 | N66: =MAX(0, G66-H66-L66) -> 236.95293 | O66: =(D66*N66)/1000 -> 54.499173
A67: 09/055 | B67: Chromo | C67: 80 | D67: 210 | E67: 1535 | G67: =IFERROR(SUMIF(Issues!B:B, A67, Issues!H:H), 0) -> 1800 | H67: =IFERROR(SUMIF(Returns!B:B, A67, Returns!H:H), 0) -> 0 | I67: 24025 | J67: 6 | K67: 124 | L67: =IFERROR((I67*(K67/8))/(39.3*J67),0) -> 1579.2515 | M67: =G67 - H67 -> 1800 | N67: =MAX(0, G67-H67-L67) -> 220.74852 | O67: =(D67*N67)/1000 -> 46.357188
A68: 09/059 | B68: Chromo | C68: 80 | D68: 126 | E68: 754 | F68: 1131 | G68: =IFERROR(SUMIF(Issues!B:B, A68, Issues!H:H), 0) -> 1700 | H68: =IFERROR(SUMIF(Returns!B:B, A68, Returns!H:H), 0) -> 580 | I68: 3500 | J68: 1 | K68: 79 | L68: =IFERROR((I68*(K68/8))/(39.3*J68),0) -> 879.45293 | M68: =G68 - H68 -> 1120 | N68: =MAX(0, G68-H68-L68) -> 240.54707 | O68: =(D68*N68)/1000 -> 30.308931
A69: 09/060 | B69: Chromo | C69: 80 | D69: 140 | E69: 945 | F69: 1300 | G69: =IFERROR(SUMIF(Issues!B:B, A69, Issues!H:H), 0) -> 1300 | H69: =IFERROR(SUMIF(Returns!B:B, A69, Returns!H:H), 0) -> 0 | I69: 3350 | J69: 1 | K69: 99 | L69: =IFERROR((I69*(K69/8))/(39.3*J69),0) -> 1054.8664 | M69: =G69 - H69 -> 1300 | N69: =MAX(0, G69-H69-L69) -> 245.13359 | O69: =(D69*N69)/1000 -> 34.318702
A70: 09/066 | B70: Chromo | C70: 80 | D70: 140 | E70: 366 | F70: 540 | G70: =IFERROR(SUMIF(Issues!B:B, A70, Issues!H:H), 0) -> 1900 | H70: =IFERROR(SUMIF(Returns!B:B, A70, Returns!H:H), 0) -> 1360 | I70: 5600 | J70: 4 | K70: 92 | L70: =IFERROR((I70*(K70/8))/(39.3*J70),0) -> 409.66921 | M70: =G70 - H70 -> 540 | N70: =MAX(0, G70-H70-L70) -> 130.33079 | O70: =(D70*N70)/1000 -> 18.24631
A71: 09/067 | B71: Chromo | C71: 80 | D71: 230 | E71: 394 | F71: 583 | G71: =IFERROR(SUMIF(Issues!B:B, A71, Issues!H:H), 0) -> 700 | H71: =IFERROR(SUMIF(Returns!B:B, A71, Returns!H:H), 0) -> 100 | I71: 7500 | J71: 6 | K71: 124 | L71: =IFERROR((I71*(K71/8))/(39.3*J71),0) -> 493.00254 | M71: =G71 - H71 -> 600 | N71: =MAX(0, G71-H71-L71) -> 106.99746 | O71: =(D71*N71)/1000 -> 24.609415
A72: 09/074 | B72: Chromo | C72: 80 | D72: 230 | E72: 394 | F72: 620 | G72: =IFERROR(SUMIF(Issues!B:B, A72, Issues!H:H), 0) -> 900 | H72: =IFERROR(SUMIF(Returns!B:B, A72, Returns!H:H), 0) -> 280 | I72: 7710 | J72: 6 | K72: 124 | L72: =IFERROR((I72*(K72/8))/(39.3*J72),0) -> 506.80662 | M72: =G72 - H72 -> 620 | N72: =MAX(0, G72-H72-L72) -> 113.19338 | O72: =(D72*N72)/1000 -> 26.034478
A73: 09/075 | B73: Chromo | C73: 80 | D73: 230 | E73: 329 | F73: 500 | G73: =IFERROR(SUMIF(Issues!B:B, A73, Issues!H:H), 0) -> 1400 | H73: =IFERROR(SUMIF(Returns!B:B, A73, Returns!H:H), 0) -> 900 | I73: 6290 | J73: 6 | K73: 124 | L73: =IFERROR((I73*(K73/8))/(39.3*J73),0) -> 413.4648 | M73: =G73 - H73 -> 500 | N73: =MAX(0, G73-H73-L73) -> 86.535199 | O73: =(D73*N73)/1000 -> 19.903096
A74: 09/041 | B74: Chromo | C74: 80 | D74: 260 | E74: 1887 | F74: 2225 | G74: =IFERROR(SUMIF(Issues!B:B, A74, Issues!H:H), 0) -> 2400 | H74: =IFERROR(SUMIF(Returns!B:B, A74, Returns!H:H), 0) -> 150 | I74: 20635 | J74: 3 | K74: 89 | L74: =IFERROR((I74*(K74/8))/(39.3*J74),0) -> 1947.1109 | M74: =G74 - H74 -> 2250 | N74: =MAX(0, G74-H74-L74) -> 302.8891 | O74: =(D74*N74)/1000 -> 78.751166
A75: 09/062 | B75: Chromo | C75: 80 | D75: 126 | E75: 628 | F75: 800 | G75: =IFERROR(SUMIF(Issues!B:B, A75, Issues!H:H), 0) -> 1250 | H75: =IFERROR(SUMIF(Returns!B:B, A75, Returns!H:H), 0) -> 400 | I75: 2850 | J75: 1 | K75: 79 | L75: =IFERROR((I75*(K75/8))/(39.3*J75),0) -> 716.12595 | M75: =G75 - H75 -> 850 | N75: =MAX(0, G75-H75-L75) -> 133.87405 | O75: =(D75*N75)/1000 -> 16.86813
A76: 09/063 | B76: Chromo | C76: 80 | D76: 140 | E76: 262 | F76: 457 | G76: =IFERROR(SUMIF(Issues!B:B, A76, Issues!H:H), 0) -> 650 | H76: =IFERROR(SUMIF(Returns!B:B, A76, Returns!H:H), 0) -> 150 | I76: 3000 | J76: 2 | K76: 66 | L76: =IFERROR((I76*(K76/8))/(39.3*J76),0) -> 314.8855 | M76: =G76 - H76 -> 500 | N76: =MAX(0, G76-H76-L76) -> 185.1145 | O76: =(D76*N76)/1000 -> 25.916031
...

Sheet Balance Stock
A1: =IFERROR(__xludf.DUMMYFUNCTION("UNIQUE(FILTER('Stock In'!C:E, 'Stock In'!C:C<>""""))"),"Material") -> Material | B1: =IFERROR(__xludf.DUMMYFUNCTION("""COMPUTED_VALUE"""),"GSM/Micron") -> GSM/Micron | C1: =IFERROR(__xludf.DUMMYFUNCTION("""COMPUTED_VALUE"""),"Web Size (mm)") -> Web Size (mm) | D1: RMT In | E1: RMT Issued | F1: RMT Returned | G1: RMT On‑Hand | H1: Sq. Mtr On‑Hand | I1: Avg Rate | J1: Stock Value
A2: =IFERROR(__xludf.DUMMYFUNCTION("""COMPUTED_VALUE"""),"Chromo") -> Chromo | B2: =IFERROR(__xludf.DUMMYFUNCTION("""COMPUTED_VALUE"""),80.0) -> 80 | C2: =IFERROR(__xludf.DUMMYFUNCTION("""COMPUTED_VALUE"""),125.0) -> 125 | D2: =IFERROR(SUMIFS('Stock In'!F:F,'Stock In'!C:C,$A2,'Stock In'!D:D,$B2,'Stock In'!E:E,$C2),0) -> 169693 | E2: =IFERROR(SUMIFS(Issues!H:H,Issues!C:C,$A2,Issues!D:D,$B2,Issues!E:E,$C2),0) -> 202047 | F2: =IFERROR(SUMIFS(Returns!H:H,Returns!C:C,$A2,Returns!D:D,$B2,Returns!E:E,$C2),0) -> 73474 | G2: =D2-E2+F2 -> 41120 | H2: =($C2*G2)/1000 -> 5140 | I2: =IFERROR( SUMIFS('Stock In'!I:I,'Stock In'!C:C,$A2,'Stock In'!D:D,$B2,'Stock In'!E:E,$C2) / SUMIFS('Stock In'!H:H,'Stock In'!C:C,$A2,'Stock In'!D:D,$B2,'Stock In'!E:E,$C2) , 0) -> 29.208838 | J2: =H2*I2 -> 150133.43
A3: =IFERROR(__xludf.DUMMYFUNCTION("""COMPUTED_VALUE"""),"Chromo") -> Chromo | B3: =IFERROR(__xludf.DUMMYFUNCTION("""COMPUTED_VALUE"""),80.0) -> 80 | C3: =IFERROR(__xludf.DUMMYFUNCTION("""COMPUTED_VALUE"""),140.0) -> 140 | D3: =IFERROR(SUMIFS('Stock In'!F:F,'Stock In'!C:C,$A3,'Stock In'!D:D,$B3,'Stock In'!E:E,$C3),0) -> 192340 | E3: =IFERROR(SUMIFS(Issues!H:H,Issues!C:C,$A3,Issues!D:D,$B3,Issues!E:E,$C3),0) -> 182781 | F3: =IFERROR(SUMIFS(Returns!H:H,Returns!C:C,$A3,Returns!D:D,$B3,Returns!E:E,$C3),0) -> 57350 | G3: =D3-E3+F3 -> 66909 | H3: =($C3*G3)/1000 -> 9367.26 | I3: =IFERROR( SUMIFS('Stock In'!I:I,'Stock In'!C:C,$A3,'Stock In'!D:D,$B3,'Stock In'!E:E,$C3) / SUMIFS('Stock In'!H:H,'Stock In'!C:C,$A3,'Stock In'!D:D,$B3,'Stock In'!E:E,$C3) , 0) -> 26.977176 | J3: =H3*I3 -> 252702.22
A4: =IFERROR(__xludf.DUMMYFUNCTION("""COMPUTED_VALUE"""),"Chromo") -> Chromo | B4: =IFERROR(__xludf.DUMMYFUNCTION("""COMPUTED_VALUE"""),80.0) -> 80 | C4: =IFERROR(__xludf.DUMMYFUNCTION("""COMPUTED_VALUE"""),150.0) -> 150 | D4: =IFERROR(SUMIFS('Stock In'!F:F,'Stock In'!C:C,$A4,'Stock In'!D:D,$B4,'Stock In'!E:E,$C4),0) -> 80040 | E4: =IFERROR(SUMIFS(Issues!H:H,Issues!C:C,$A4,Issues!D:D,$B4,Issues!E:E,$C4),0) -> 54310 | F4: =IFERROR(SUMIFS(Returns!H:H,Returns!C:C,$A4,Returns!D:D,$B4,Returns!E:E,$C4),0) -> 15150 | G4: =D4-E4+F4 -> 40880 | H4: =($C4*G4)/1000 -> 6132 | I4: =IFERROR( SUMIFS('Stock In'!I:I,'Stock In'!C:C,$A4,'Stock In'!D:D,$B4,'Stock In'!E:E,$C4) / SUMIFS('Stock In'!H:H,'Stock In'!C:C,$A4,'Stock In'!D:D,$B4,'Stock In'!E:E,$C4) , 0) -> 29.874453 | J4: =H4*I4 -> 183190.14
A5: =IFERROR(__xludf.DUMMYFUNCTION("""COMPUTED_VALUE"""),"Chromo") -> Chromo | B5: =IFERROR(__xludf.DUMMYFUNCTION("""COMPUTED_VALUE"""),80.0) -> 80 | C5: =IFERROR(__xludf.DUMMYFUNCTION("""COMPUTED_VALUE"""),160.0) -> 160 | D5: =IFERROR(SUMIFS('Stock In'!F:F,'Stock In'!C:C,$A5,'Stock In'!D:D,$B5,'Stock In'!E:E,$C5),0) -> 283870 | E5: =IFERROR(SUMIFS(Issues!H:H,Issues!C:C,$A5,Issues!D:D,$B5,Issues!E:E,$C5),0) -> 233235 | F5: =IFERROR(SUMIFS(Returns!H:H,Returns!C:C,$A5,Returns!D:D,$B5,Returns!E:E,$C5),0) -> 48822 | G5: =D5-E5+F5 -> 99457 | H5: =($C5*G5)/1000 -> 15913.12 | I5: =IFERROR( SUMIFS('Stock In'!I:I,'Stock In'!C:C,$A5,'Stock In'!D:D,$B5,'Stock In'!E:E,$C5) / SUMIFS('Stock In'!H:H,'Stock In'!C:C,$A5,'Stock In'!D:D,$B5,'Stock In'!E:E,$C5) , 0) -> 27.344801 | J5: =H5*I5 -> 435141.1
A6: =IFERROR(__xludf.DUMMYFUNCTION("""COMPUTED_VALUE"""),"Chromo") -> Chromo | B6: =IFERROR(__xludf.DUMMYFUNCTION("""COMPUTED_VALUE"""),80.0) -> 80 | C6: =IFERROR(__xludf.DUMMYFUNCTION("""COMPUTED_VALUE"""),170.0) -> 170 | D6: =IFERROR(SUMIFS('Stock In'!F:F,'Stock In'!C:C,$A6,'Stock In'!D:D,$B6,'Stock In'!E:E,$C6),0) -> 75820 | E6: =IFERROR(SUMIFS(Issues!H:H,Issues!C:C,$A6,Issues!D:D,$B6,Issues!E:E,$C6),0) -> 46330 | F6: =IFERROR(SUMIFS(Returns!H:H,Returns!C:C,$A6,Returns!D:D,$B6,Returns!E:E,$C6),0) -> 20380 | G6: =D6-E6+F6 -> 49870 | H6: =($C6*G6)/1000 -> 8477.9 | I6: =IFERROR( SUMIFS('Stock In'!I:I,'Stock In'!C:C,$A6,'Stock In'!D:D,$B6,'Stock In'!E:E,$C6) / SUMIFS('Stock In'!H:H,'Stock In'!C:C,$A6,'Stock In'!D:D,$B6,'Stock In'!E:E,$C6) , 0) -> 30.678082 | J6: =H6*I6 -> 260085.71
A7: =IFERROR(__xludf.DUMMYFUNCTION("""COMPUTED_VALUE"""),"Chromo") -> Chromo | B7: =IFERROR(__xludf.DUMMYFUNCTION("""COMPUTED_VALUE"""),60.0) -> 60 | C7: =IFERROR(__xludf.DUMMYFUNCTION("""COMPUTED_VALUE"""),170.0) -> 170 | D7: =IFERROR(SUMIFS('Stock In'!F:F,'Stock In'!C:C,$A7,'Stock In'!D:D,$B7,'Stock In'!E:E,$C7),0) -> 2200 | E7: =IFERROR(SUMIFS(Issues!H:H,Issues!C:C,$A7,Issues!D:D,$B7,Issues!E:E,$C7),0) -> 0 | F7: =IFERROR(SUMIFS(Returns!H:H,Returns!C:C,$A7,Returns!D:D,$B7,Returns!E:E,$C7),0) -> 0 | G7: =D7-E7+F7 -> 2200 | H7: =($C7*G7)/1000 -> 374 | I7: =IFERROR( SUMIFS('Stock In'!I:I,'Stock In'!C:C,$A7,'Stock In'!D:D,$B7,'Stock In'!E:E,$C7) / SUMIFS('Stock In'!H:H,'Stock In'!C:C,$A7,'Stock In'!D:D,$B7,'Stock In'!E:E,$C7) , 0) -> 29 | J7: =H7*I7 -> 10846
A8: =IFERROR(__xludf.DUMMYFUNCTION("""COMPUTED_VALUE"""),"Chromo") -> Chromo | B8: =IFERROR(__xludf.DUMMYFUNCTION("""COMPUTED_VALUE"""),80.0) -> 80 | C8: =IFERROR(__xludf.DUMMYFUNCTION("""COMPUTED_VALUE"""),180.0) -> 180 | D8: =IFERROR(SUMIFS('Stock In'!F:F,'Stock In'!C:C,$A8,'Stock In'!D:D,$B8,'Stock In'!E:E,$C8),0) -> 140675 | E8: =IFERROR(SUMIFS(Issues!H:H,Issues!C:C,$A8,Issues!D:D,$B8,Issues!E:E,$C8),0) -> 97939 | F8: =IFERROR(SUMIFS(Returns!H:H,Returns!C:C,$A8,Returns!D:D,$B8,Returns!E:E,$C8),0) -> 33148 | G8: =D8-E8+F8 -> 75884 | H8: =($C8*G8)/1000 -> 13659.12 | I8: =IFERROR( SUMIFS('Stock In'!I:I,'Stock In'!C:C,$A8,'Stock In'!D:D,$B8,'Stock In'!E:E,$C8) / SUMIFS('Stock In'!H:H,'Stock In'!C:C,$A8,'Stock In'!D:D,$B8,'Stock In'!E:E,$C8) , 0) -> 29.987459 | J8: =H8*I8 -> 409602.3
A9: =IFERROR(__xludf.DUMMYFUNCTION("""COMPUTED_VALUE"""),"Chromo") -> Chromo | B9: =IFERROR(__xludf.DUMMYFUNCTION("""COMPUTED_VALUE"""),80.0) -> 80 | C9: =IFERROR(__xludf.DUMMYFUNCTION("""COMPUTED_VALUE"""),190.0) -> 190 | D9: =IFERROR(SUMIFS('Stock In'!F:F,'Stock In'!C:C,$A9,'Stock In'!D:D,$B9,'Stock In'!E:E,$C9),0) -> 33500 | E9: =IFERROR(SUMIFS(Issues!H:H,Issues!C:C,$A9,Issues!D:D,$B9,Issues!E:E,$C9),0) -> 5550 | F9: =IFERROR(SUMIFS(Returns!H:H,Returns!C:C,$A9,Returns!D:D,$B9,Returns!E:E,$C9),0) -> 2490 | G9: =D9-E9+F9 -> 30440 | H9: =($C9*G9)/1000 -> 5783.6 | I9: =IFERROR( SUMIFS('Stock In'!I:I,'Stock In'!C:C,$A9,'Stock In'!D:D,$B9,'Stock In'!E:E,$C9) / SUMIFS('Stock In'!H:H,'Stock In'!C:C,$A9,'Stock In'!D:D,$B9,'Stock In'!E:E,$C9) , 0) -> 41.384687 | J9: =H9*I9 -> 239352.47
A10: =IFERROR(__xludf.DUMMYFUNCTION("""COMPUTED_VALUE"""),"Chromo") -> Chromo | B10: =IFERROR(__xludf.DUMMYFUNCTION("""COMPUTED_VALUE"""),80.0) -> 80 | C10: =IFERROR(__xludf.DUMMYFUNCTION("""COMPUTED_VALUE"""),210.0) -> 210 | D10: =IFERROR(SUMIFS('Stock In'!F:F,'Stock In'!C:C,$A10,'Stock In'!D:D,$B10,'Stock In'!E:E,$C10),0) -> 140235 | E10: =IFERROR(SUMIFS(Issues!H:H,Issues!C:C,$A10,Issues!D:D,$B10,Issues!E:E,$C10),0) -> 120665 | F10: =IFERROR(SUMIFS(Returns!H:H,Returns!C:C,$A10,Returns!D:D,$B10,Returns!E:E,$C10),0) -> 44414 | G10: =D10-E10+F10 -> 63984 | H10: =($C10*G10)/1000 -> 13436.64 | I10: =IFERROR( SUMIFS('Stock In'!I:I,'Stock In'!C:C,$A10,'Stock In'!D:D,$B10,'Stock In'!E:E,$C10) / SUMIFS('Stock In'!H:H,'Stock In'!C:C,$A10,'Stock In'!D:D,$B10,'Stock In'!E:E,$C10) , 0) -> 29.572987 | J10: =H10*I10 -> 397361.59
A11: =IFERROR(__xludf.DUMMYFUNCTION("""COMPUTED_VALUE"""),"Chromo") -> Chromo | B11: =IFERROR(__xludf.DUMMYFUNCTION("""COMPUTED_VALUE"""),80.0) -> 80 | C11: =IFERROR(__xludf.DUMMYFUNCTION("""COMPUTED_VALUE"""),250.0) -> 250 | D11: =IFERROR(SUMIFS('Stock In'!F:F,'Stock In'!C:C,$A11,'Stock In'!D:D,$B11,'Stock In'!E:E,$C11),0) -> 190997 | E11: =IFERROR(SUMIFS(Issues!H:H,Issues!C:C,$A11,Issues!D:D,$B11,Issues!E:E,$C11),0) -> 172620 | F11: =IFERROR(SUMIFS(Returns!H:H,Returns!C:C,$A11,Returns!D:D,$B11,Returns!E:E,$C11),0) -> 27670 | G11: =D11-E11+F11 -> 46047 | H11: =($C11*G11)/1000 -> 11511.75 | I11: =IFERROR( SUMIFS('Stock In'!I:I,'Stock In'!C:C,$A11,'Stock In'!D:D,$B11,'Stock In'!E:E,$C11) / SUMIFS('Stock In'!H:H,'Stock In'!C:C,$A11,'Stock In'!D:D,$B11,'Stock In'!E:E,$C11) , 0) -> 50.973769 | J11: =H11*I11 -> 586797.28
A12: =IFERROR(__xludf.DUMMYFUNCTION("""COMPUTED_VALUE"""),"Chromo") -> Chromo | B12: =IFERROR(__xludf.DUMMYFUNCTION("""COMPUTED_VALUE"""),80.0) -> 80 | C12: =IFERROR(__xludf.DUMMYFUNCTION("""COMPUTED_VALUE"""),280.0) -> 280 | D12: =IFERROR(SUMIFS('Stock In'!F:F,'Stock In'!C:C,$A12,'Stock In'!D:D,$B12,'Stock In'!E:E,$C12),0) -> 53025 | E12: =IFERROR(SUMIFS(Issues!H:H,Issues!C:C,$A12,Issues!D:D,$B12,Issues!E:E,$C12),0) -> 57625 | F12: =IFERROR(SUMIFS(Returns!H:H,Returns!C:C,$A12,Returns!D:D,$B12,Returns!E:E,$C12),0) -> 13780 | G12: =D12-E12+F12 -> 9180 | H12: =($C12*G12)/1000 -> 2570.4 | I12: =IFERROR( SUMIFS('Stock In'!I:I,'Stock In'!C:C,$A12,'Stock In'!D:D,$B12,'Stock In'!E:E,$C12) / SUMIFS('Stock In'!H:H,'Stock In'!C:C,$A12,'Stock In'!D:D,$B12,'Stock In'!E:E,$C12) , 0) -> 29.072353 | J12: =H12*I12 -> 74727.575
A13: =IFERROR(__xludf.DUMMYFUNCTION("""COMPUTED_VALUE"""),"Chromo") -> Chromo | B13: =IFERROR(__xludf.DUMMYFUNCTION("""COMPUTED_VALUE"""),80.0) -> 80 | C13: =IFERROR(__xludf.DUMMYFUNCTION("""COMPUTED_VALUE"""),290.0) -> 290 | D13: =IFERROR(SUMIFS('Stock In'!F:F,'Stock In'!C:C,$A13,'Stock In'!D:D,$B13,'Stock In'!E:E,$C13),0) -> 363040 | E13: =IFERROR(SUMIFS(Issues!H:H,Issues!C:C,$A13,Issues!D:D,$B13,Issues!E:E,$C13),0) -> 310420 | F13: =IFERROR(SUMIFS(Returns!H:H,Returns!C:C,$A13,Returns!D:D,$B13,Returns!E:E,$C13),0) -> 54180 | G13: =D13-E13+F13 -> 106800 | H13: =($C13*G13)/1000 -> 30972 | I13: =IFERROR( SUMIFS('Stock In'!I:I,'Stock In'!C:C,$A13,'Stock In'!D:D,$B13,'Stock In'!E:E,$C13) / SUMIFS('Stock In'!H:H,'Stock In'!C:C,$A13,'Stock In'!D:D,$B13,'Stock In'!E:E,$C13) , 0) -> 29.519821 | J13: =H13*I13 -> 914287.9
A14: =IFERROR(__xludf.DUMMYFUNCTION("""COMPUTED_VALUE"""),"C-MIRRORCOAT") -> C-MIRRORCOAT | B14: =IFERROR(__xludf.DUMMYFUNCTION("""COMPUTED_VALUE"""),80.0) -> 80 | C14: =IFERROR(__xludf.DUMMYFUNCTION("""COMPUTED_VALUE"""),290.0) -> 290 | D14: =IFERROR(SUMIFS('Stock In'!F:F,'Stock In'!C:C,$A14,'Stock In'!D:D,$B14,'Stock In'!E:E,$C14),0) -> 4920 | E14: =IFERROR(SUMIFS(Issues!H:H,Issues!C:C,$A14,Issues!D:D,$B14,Issues!E:E,$C14),0) -> 0 | F14: =IFERROR(SUMIFS(Returns!H:H,Returns!C:C,$A14,Returns!D:D,$B14,Returns!E:E,$C14),0) -> 0 | G14: =D14-E14+F14 -> 4920 | H14: =($C14*G14)/1000 -> 1426.8 | I14: =IFERROR( SUMIFS('Stock In'!I:I,'Stock In'!C:C,$A14,'Stock In'!D:D,$B14,'Stock In'!E:E,$C14) / SUMIFS('Stock In'!H:H,'Stock In'!C:C,$A14,'Stock In'!D:D,$B14,'Stock In'!E:E,$C14) , 0) -> 46.780813 | J14: =H14*I14 -> 66746.864
A15: =IFERROR(__xludf.DUMMYFUNCTION("""COMPUTED_VALUE"""),"C-MIRRORCOAT") -> C-MIRRORCOAT | B15: =IFERROR(__xludf.DUMMYFUNCTION("""COMPUTED_VALUE"""),80.0) -> 80 | C15: =IFERROR(__xludf.DUMMYFUNCTION("""COMPUTED_VALUE"""),300.0) -> 300 | D15: =IFERROR(SUMIFS('Stock In'!F:F,'Stock In'!C:C,$A15,'Stock In'!D:D,$B15,'Stock In'!E:E,$C15),0) -> 2000 | E15: =IFERROR(SUMIFS(Issues!H:H,Issues!C:C,$A15,Issues!D:D,$B15,Issues!E:E,$C15),0) -> 0 | F15: =IFERROR(SUMIFS(Returns!H:H,Returns!C:C,$A15,Returns!D:D,$B15,Returns!E:E,$C15),0) -> 0 | G15: =D15-E15+F15 -> 2000 | H15: =($C15*G15)/1000 -> 600 | I15: =IFERROR( SUMIFS('Stock In'!I:I,'Stock In'!C:C,$A15,'Stock In'!D:D,$B15,'Stock In'!E:E,$C15) / SUMIFS('Stock In'!H:H,'Stock In'!C:C,$A15,'Stock In'!D:D,$B15,'Stock In'!E:E,$C15) , 0) -> 46 | J15: =H15*I15 -> 27600
A16: =IFERROR(__xludf.DUMMYFUNCTION("""COMPUTED_VALUE"""),"Chromo") -> Chromo | B16: =IFERROR(__xludf.DUMMYFUNCTION("""COMPUTED_VALUE"""),80.0) -> 80 | C16: =IFERROR(__xludf.DUMMYFUNCTION("""COMPUTED_VALUE"""),300.0) -> 300 | D16: =IFERROR(SUMIFS('Stock In'!F:F,'Stock In'!C:C,$A16,'Stock In'!D:D,$B16,'Stock In'!E:E,$C16),0) -> 54665 | E16: =IFERROR(SUMIFS(Issues!H:H,Issues!C:C,$A16,Issues!D:D,$B16,Issues!E:E,$C16),0) -> 51250 | F16: =IFERROR(SUMIFS(Returns!H:H,Returns!C:C,$A16,Returns!D:D,$B16,Returns!E:E,$C16),0) -> 8450 | G16: =D16-E16+F16 -> 11865 | H16: =($C16*G16)/1000 -> 3559.5 | I16: =IFERROR( SUMIFS('Stock In'!I:I,'Stock In'!C:C,$A16,'Stock In'!D:D,$B16,'Stock In'!E:E,$C16) / SUMIFS('Stock In'!H:H,'Stock In'!C:C,$A16,'Stock In'!D:D,$B16,'Stock In'!E:E,$C16) , 0) -> 29.345565 | J16: =H16*I16 -> 104455.54
A17: =IFERROR(__xludf.DUMMYFUNCTION("""COMPUTED_VALUE"""),"Chromo") -> Chromo | B17: =IFERROR(__xludf.DUMMYFUNCTION("""COMPUTED_VALUE"""),80.0) -> 80 | C17: =IFERROR(__xludf.DUMMYFUNCTION("""COMPUTED_VALUE"""),320.0) -> 320 | D17: =IFERROR(SUMIFS('Stock In'!F:F,'Stock In'!C:C,$A17,'Stock In'!D:D,$B17,'Stock In'!E:E,$C17),0) -> 46465 | E17: =IFERROR(SUMIFS(Issues!H:H,Issues!C:C,$A17,Issues!D:D,$B17,Issues!E:E,$C17),0) -> 41450 | F17: =IFERROR(SUMIFS(Returns!H:H,Returns!C:C,$A17,Returns!D:D,$B17,Returns!E:E,$C17),0) -> 16756 | G17: =D17-E17+F17 -> 21771 | H17: =($C17*G17)/1000 -> 6966.72 | I17: =IFERROR( SUMIFS('Stock In'!I:I,'Stock In'!C:C,$A17,'Stock In'!D:D,$B17,'Stock In'!E:E,$C17) / SUMIFS('Stock In'!H:H,'Stock In'!C:C,$A17,'Stock In'!D:D,$B17,'Stock In'!E:E,$C17) , 0) -> 29.469321 | J17: =H17*I17 -> 205304.51
A18: =IFERROR(__xludf.DUMMYFUNCTION("""COMPUTED_VALUE"""),"Chromo") -> Chromo | B18: =IFERROR(__xludf.DUMMYFUNCTION("""COMPUTED_VALUE"""),80.0) -> 80 | C18: =IFERROR(__xludf.DUMMYFUNCTION("""COMPUTED_VALUE"""),330.0) -> 330 | D18: =IFERROR(SUMIFS('Stock In'!F:F,'Stock In'!C:C,$A18,'Stock In'!D:D,$B18,'Stock In'!E:E,$C18),0) -> 87760 | E18: =IFERROR(SUMIFS(Issues!H:H,Issues!C:C,$A18,Issues!D:D,$B18,Issues!E:E,$C18),0) -> 82016 | F18: =IFERROR(SUMIFS(Returns!H:H,Returns!C:C,$A18,Returns!D:D,$B18,Returns!E:E,$C18),0) -> 24010 | G18: =D18-E18+F18 -> 29754 | H18: =($C18*G18)/1000 -> 9818.82 | I18: =IFERROR( SUMIFS('Stock In'!I:I,'Stock In'!C:C,$A18,'Stock In'!D:D,$B18,'Stock In'!E:E,$C18) / SUMIFS('Stock In'!H:H,'Stock In'!C:C,$A18,'Stock In'!D:D,$B18,'Stock In'!E:E,$C18) , 0) -> 29.723114 | J18: =H18*I18 -> 291845.91
A19: =IFERROR(__xludf.DUMMYFUNCTION("""COMPUTED_VALUE"""),"C-MIRRORCOAT") -> C-MIRRORCOAT | B19: =IFERROR(__xludf.DUMMYFUNCTION("""COMPUTED_VALUE"""),80.0) -> 80 | C19: =IFERROR(__xludf.DUMMYFUNCTION("""COMPUTED_VALUE"""),330.0) -> 330 | D19: =IFERROR(SUMIFS('Stock In'!F:F,'Stock In'!C:C,$A19,'Stock In'!D:D,$B19,'Stock In'!E:E,$C19),0) -> 2000 | E19: =IFERROR(SUMIFS(Issues!H:H,Issues!C:C,$A19,Issues!D:D,$B19,Issues!E:E,$C19),0) -> 0 | F19: =IFERROR(SUMIFS(Returns!H:H,Returns!C:C,$A19,Returns!D:D,$B19,Returns!E:E,$C19),0) -> 0 | G19: =D19-E19+F19 -> 2000 | H19: =($C19*G19)/1000 -> 660 | I19: =IFERROR( SUMIFS('Stock In'!I:I,'Stock In'!C:C,$A19,'Stock In'!D:D,$B19,'Stock In'!E:E,$C19) / SUMIFS('Stock In'!H:H,'Stock In'!C:C,$A19,'Stock In'!D:D,$B19,'Stock In'!E:E,$C19) , 0) -> 46 | J19: =H19*I19 -> 30360
A20: =IFERROR(__xludf.DUMMYFUNCTION("""COMPUTED_VALUE"""),"P G BACK") -> P G BACK | B20: =IFERROR(__xludf.DUMMYFUNCTION("""COMPUTED_VALUE"""),150.0) -> 150 | C20: =IFERROR(__xludf.DUMMYFUNCTION("""COMPUTED_VALUE"""),90.0) -> 90 | D20: =IFERROR(SUMIFS('Stock In'!F:F,'Stock In'!C:C,$A20,'Stock In'!D:D,$B20,'Stock In'!E:E,$C20),0) -> 500 | E20: =IFERROR(SUMIFS(Issues!H:H,Issues!C:C,$A20,Issues!D:D,$B20,Issues!E:E,$C20),0) -> 0 | F20: =IFERROR(SUMIFS(Returns!H:H,Returns!C:C,$A20,Returns!D:D,$B20,Returns!E:E,$C20),0) -> 0 | G20: =D20-E20+F20 -> 500 | H20: =($C20*G20)/1000 -> 45 | I20: =IFERROR( SUMIFS('Stock In'!I:I,'Stock In'!C:C,$A20,'Stock In'!D:D,$B20,'Stock In'!E:E,$C20) / SUMIFS('Stock In'!H:H,'Stock In'!C:C,$A20,'Stock In'!D:D,$B20,'Stock In'!E:E,$C20) , 0) -> 53.5 | J20: =H20*I20 -> 2407.5
A21: =IFERROR(__xludf.DUMMYFUNCTION("""COMPUTED_VALUE"""),"PP CLEAR") -> PP CLEAR | B21: =IFERROR(__xludf.DUMMYFUNCTION("""COMPUTED_VALUE"""),50.0) -> 50 | C21: =IFERROR(__xludf.DUMMYFUNCTION("""COMPUTED_VALUE"""),200.0) -> 200 | D21: =IFERROR(SUMIFS('Stock In'!F:F,'Stock In'!C:C,$A21,'Stock In'!D:D,$B21,'Stock In'!E:E,$C21),0) -> 19580 | E21: =IFERROR(SUMIFS(Issues!H:H,Issues!C:C,$A21,Issues!D:D,$B21,Issues!E:E,$C21),0) -> 12400 | F21: =IFERROR(SUMIFS(Returns!H:H,Returns!C:C,$A21,Returns!D:D,$B21,Returns!E:E,$C21),0) -> 310 | G21: =D21-E21+F21 -> 7490 | H21: =($C21*G21)/1000 -> 1498 | I21: =IFERROR( SUMIFS('Stock In'!I:I,'Stock In'!C:C,$A21,'Stock In'!D:D,$B21,'Stock In'!E:E,$C21) / SUMIFS('Stock In'!H:H,'Stock In'!C:C,$A21,'Stock In'!D:D,$B21,'Stock In'!E:E,$C21) , 0) -> 37.991318 | J21: =H21*I21 -> 56910.994
A22: =IFERROR(__xludf.DUMMYFUNCTION("""COMPUTED_VALUE"""),"PP WHITE") -> PP WHITE | B22: =IFERROR(__xludf.DUMMYFUNCTION("""COMPUTED_VALUE"""),50.0) -> 50 | C22: =IFERROR(__xludf.DUMMYFUNCTION("""COMPUTED_VALUE"""),200.0) -> 200 | D22: =IFERROR(SUMIFS('Stock In'!F:F,'Stock In'!C:C,$A22,'Stock In'!D:D,$B22,'Stock In'!E:E,$C22),0) -> 6170 | E22: =IFERROR(SUMIFS(Issues!H:H,Issues!C:C,$A22,Issues!D:D,$B22,Issues!E:E,$C22),0) -> 1800 | F22: =IFERROR(SUMIFS(Returns!H:H,Returns!C:C,$A22,Returns!D:D,$B22,Returns!E:E,$C22),0) -> 0 | G22: =D22-E22+F22 -> 4370 | H22: =($C22*G22)/1000 -> 874 | I22: =IFERROR( SUMIFS('Stock In'!I:I,'Stock In'!C:C,$A22,'Stock In'!D:D,$B22,'Stock In'!E:E,$C22) / SUMIFS('Stock In'!H:H,'Stock In'!C:C,$A22,'Stock In'!D:D,$B22,'Stock In'!E:E,$C22) , 0) -> 36.275527 | J22: =H22*I22 -> 31704.81
A23: =IFERROR(__xludf.DUMMYFUNCTION("""COMPUTED_VALUE"""),"SILVER PAPER") -> SILVER PAPER | B23: =IFERROR(__xludf.DUMMYFUNCTION("""COMPUTED_VALUE"""),80.0) -> 80 | C23: =IFERROR(__xludf.DUMMYFUNCTION("""COMPUTED_VALUE"""),280.0) -> 280 | D23: =IFERROR(SUMIFS('Stock In'!F:F,'Stock In'!C:C,$A23,'Stock In'!D:D,$B23,'Stock In'!E:E,$C23),0) -> 5260 | E23: =IFERROR(SUMIFS(Issues!H:H,Issues!C:C,$A23,Issues!D:D,$B23,Issues!E:E,$C23),0) -> 6530 | F23: =IFERROR(SUMIFS(Returns!H:H,Returns!C:C,$A23,Returns!D:D,$B23,Returns!E:E,$C23),0) -> 900 | G23: =D23-E23+F23 -> -370 | H23: =($C23*G23)/1000 -> -103.6 | I23: =IFERROR( SUMIFS('Stock In'!I:I,'Stock In'!C:C,$A23,'Stock In'!D:D,$B23,'Stock In'!E:E,$C23) / SUMIFS('Stock In'!H:H,'Stock In'!C:C,$A23,'Stock In'!D:D,$B23,'Stock In'!E:E,$C23) , 0) -> 41.180133 | J23: =H23*I23 -> -4266.2618
A24: =IFERROR(__xludf.DUMMYFUNCTION("""COMPUTED_VALUE"""),"DOUBLE SILICON (P G BACK)") -> DOUBLE SILICON (P G BACK) | B24: =IFERROR(__xludf.DUMMYFUNCTION("""COMPUTED_VALUE"""),150.0) -> 150 | C24: =IFERROR(__xludf.DUMMYFUNCTION("""COMPUTED_VALUE"""),180.0) -> 180 | D24: =IFERROR(SUMIFS('Stock In'!F:F,'Stock In'!C:C,$A24,'Stock In'!D:D,$B24,'Stock In'!E:E,$C24),0) -> 1500 | E24: =IFERROR(SUMIFS(Issues!H:H,Issues!C:C,$A24,Issues!D:D,$B24,Issues!E:E,$C24),0) -> 0 | F24: =IFERROR(SUMIFS(Returns!H:H,Returns!C:C,$A24,Returns!D:D,$B24,Returns!E:E,$C24),0) -> 0 | G24: =D24-E24+F24 -> 1500 | H24: =($C24*G24)/1000 -> 270 | I24: =IFERROR( SUMIFS('Stock In'!I:I,'Stock In'!C:C,$A24,'Stock In'!D:D,$B24,'Stock In'!E:E,$C24) / SUMIFS('Stock In'!H:H,'Stock In'!C:C,$A24,'Stock In'!D:D,$B24,'Stock In'!E:E,$C24) , 0) -> 53.5 | J24: =H24*I24 -> 14445
A25: =IFERROR(__xludf.DUMMYFUNCTION("""COMPUTED_VALUE"""),"DOUBLE SILICON (P G BACK)") -> DOUBLE SILICON (P G BACK) | B25: =IFERROR(__xludf.DUMMYFUNCTION("""COMPUTED_VALUE"""),150.0) -> 150 | C25: =IFERROR(__xludf.DUMMYFUNCTION("""COMPUTED_VALUE"""),100.0) -> 100 | D25: =IFERROR(SUMIFS('Stock In'!F:F,'Stock In'!C:C,$A25,'Stock In'!D:D,$B25,'Stock In'!E:E,$C25),0) -> 1500 | E25: =IFERROR(SUMIFS(Issues!H:H,Issues!C:C,$A25,Issues!D:D,$B25,Issues!E:E,$C25),0) -> 0 | F25: =IFERROR(SUMIFS(Returns!H:H,Returns!C:C,$A25,Returns!D:D,$B25,Returns!E:E,$C25),0) -> 0 | G25: =D25-E25+F25 -> 1500 | H25: =($C25*G25)/1000 -> 150 | I25: =IFERROR( SUMIFS('Stock In'!I:I,'Stock In'!C:C,$A25,'Stock In'!D:D,$B25,'Stock In'!E:E,$C25) / SUMIFS('Stock In'!H:H,'Stock In'!C:C,$A25,'Stock In'!D:D,$B25,'Stock In'!E:E,$C25) , 0) -> 53.5 | J25: =H25*I25 -> 8025
A26: =IFERROR(__xludf.DUMMYFUNCTION("""COMPUTED_VALUE"""),"clear on clear") -> clear on clear | B26: =IFERROR(__xludf.DUMMYFUNCTION("""COMPUTED_VALUE"""),50.0) -> 50 | C26: =IFERROR(__xludf.DUMMYFUNCTION("""COMPUTED_VALUE"""),250.0) -> 250 | D26: =IFERROR(SUMIFS('Stock In'!F:F,'Stock In'!C:C,$A26,'Stock In'!D:D,$B26,'Stock In'!E:E,$C26),0) -> 1000 | E26: =IFERROR(SUMIFS(Issues!H:H,Issues!C:C,$A26,Issues!D:D,$B26,Issues!E:E,$C26),0) -> 0 | F26: =IFERROR(SUMIFS(Returns!H:H,Returns!C:C,$A26,Returns!D:D,$B26,Returns!E:E,$C26),0) -> 0 | G26: =D26-E26+F26 -> 1000 | H26: =($C26*G26)/1000 -> 250 | I26: =IFERROR( SUMIFS('Stock In'!I:I,'Stock In'!C:C,$A26,'Stock In'!D:D,$B26,'Stock In'!E:E,$C26) / SUMIFS('Stock In'!H:H,'Stock In'!C:C,$A26,'Stock In'!D:D,$B26,'Stock In'!E:E,$C26) , 0) -> 62 | J26: =H26*I26 -> 15500
A27: =IFERROR(__xludf.DUMMYFUNCTION("""COMPUTED_VALUE"""),"PET MATT") -> PET MATT | B27: =IFERROR(__xludf.DUMMYFUNCTION("""COMPUTED_VALUE"""),50.0) -> 50 | C27: =IFERROR(__xludf.DUMMYFUNCTION("""COMPUTED_VALUE"""),175.0) -> 175 | D27: =IFERROR(SUMIFS('Stock In'!F:F,'Stock In'!C:C,$A27,'Stock In'!D:D,$B27,'Stock In'!E:E,$C27),0) -> 600 | E27: =IFERROR(SUMIFS(Issues!H:H,Issues!C:C,$A27,Issues!D:D,$B27,Issues!E:E,$C27),0) -> 0 | F27: =IFERROR(SUMIFS(Returns!H:H,Returns!C:C,$A27,Returns!D:D,$B27,Returns!E:E,$C27),0) -> 0 | G27: =D27-E27+F27 -> 600 | H27: =($C27*G27)/1000 -> 105 | I27: =IFERROR( SUMIFS('Stock In'!I:I,'Stock In'!C:C,$A27,'Stock In'!D:D,$B27,'Stock In'!E:E,$C27) / SUMIFS('Stock In'!H:H,'Stock In'!C:C,$A27,'Stock In'!D:D,$B27,'Stock In'!E:E,$C27) , 0) -> 0 | J27: =H27*I27 -> 0
A28: =IFERROR(__xludf.DUMMYFUNCTION("""COMPUTED_VALUE"""),"Chromo") -> Chromo | B28: =IFERROR(__xludf.DUMMYFUNCTION("""COMPUTED_VALUE"""),80.0) -> 80 | C28: =IFERROR(__xludf.DUMMYFUNCTION("""COMPUTED_VALUE"""),195.0) -> 195 | D28: =IFERROR(SUMIFS('Stock In'!F:F,'Stock In'!C:C,$A28,'Stock In'!D:D,$B28,'Stock In'!E:E,$C28),0) -> 28790 | E28: =IFERROR(SUMIFS(Issues!H:H,Issues!C:C,$A28,Issues!D:D,$B28,Issues!E:E,$C28),0) -> 32120 | F28: =IFERROR(SUMIFS(Returns!H:H,Returns!C:C,$A28,Returns!D:D,$B28,Returns!E:E,$C28),0) -> 11950 | G28: =D28-E28+F28 -> 8620 | H28: =($C28*G28)/1000 -> 1680.9 | I28: =IFERROR( SUMIFS('Stock In'!I:I,'Stock In'!C:C,$A28,'Stock In'!D:D,$B28,'Stock In'!E:E,$C28) / SUMIFS('Stock In'!H:H,'Stock In'!C:C,$A28,'Stock In'!D:D,$B28,'Stock In'!E:E,$C28) , 0) -> 26.498437 | J28: =H28*I28 -> 44541.223
A29: =IFERROR(__xludf.DUMMYFUNCTION("""COMPUTED_VALUE"""),"PP WHITE MATT") -> PP WHITE MATT | B29: =IFERROR(__xludf.DUMMYFUNCTION("""COMPUTED_VALUE"""),50.0) -> 50 | C29: =IFERROR(__xludf.DUMMYFUNCTION("""COMPUTED_VALUE"""),200.0) -> 200 | D29: =IFERROR(SUMIFS('Stock In'!F:F,'Stock In'!C:C,$A29,'Stock In'!D:D,$B29,'Stock In'!E:E,$C29),0) -> 1500 | E29: =IFERROR(SUMIFS(Issues!H:H,Issues!C:C,$A29,Issues!D:D,$B29,Issues!E:E,$C29),0) -> 0 | F29: =IFERROR(SUMIFS(Returns!H:H,Returns!C:C,$A29,Returns!D:D,$B29,Returns!E:E,$C29),0) -> 0 | G29: =D29-E29+F29 -> 1500 | H29: =($C29*G29)/1000 -> 300 | I29: =IFERROR( SUMIFS('Stock In'!I:I,'Stock In'!C:C,$A29,'Stock In'!D:D,$B29,'Stock In'!E:E,$C29) / SUMIFS('Stock In'!H:H,'Stock In'!C:C,$A29,'Stock In'!D:D,$B29,'Stock In'!E:E,$C29) , 0) -> 34.5 | J29: =H29*I29 -> 10350
A30: =IFERROR(__xludf.DUMMYFUNCTION("""COMPUTED_VALUE"""),"Chromo") -> Chromo | B30: =IFERROR(__xludf.DUMMYFUNCTION("""COMPUTED_VALUE"""),80.0) -> 80 | C30: =IFERROR(__xludf.DUMMYFUNCTION("""COMPUTED_VALUE"""),220.0) -> 220 | D30: =IFERROR(SUMIFS('Stock In'!F:F,'Stock In'!C:C,$A30,'Stock In'!D:D,$B30,'Stock In'!E:E,$C30),0) -> 42780 | E30: =IFERROR(SUMIFS(Issues!H:H,Issues!C:C,$A30,Issues!D:D,$B30,Issues!E:E,$C30),0) -> 11250 | F30: =IFERROR(SUMIFS(Returns!H:H,Returns!C:C,$A30,Returns!D:D,$B30,Returns!E:E,$C30),0) -> 840 | G30: =D30-E30+F30 -> 32370 | H30: =($C30*G30)/1000 -> 7121.4 | I30: =IFERROR( SUMIFS('Stock In'!I:I,'Stock In'!C:C,$A30,'Stock In'!D:D,$B30,'Stock In'!E:E,$C30) / SUMIFS('Stock In'!H:H,'Stock In'!C:C,$A30,'Stock In'!D:D,$B30,'Stock In'!E:E,$C30) , 0) -> 27.423095 | J30: =H30*I30 -> 195290.83
A31: =IFERROR(__xludf.DUMMYFUNCTION("""COMPUTED_VALUE"""),"Chromo") -> Chromo | B31: =IFERROR(__xludf.DUMMYFUNCTION("""COMPUTED_VALUE"""),80.0) -> 80 | C31: =IFERROR(__xludf.DUMMYFUNCTION("""COMPUTED_VALUE"""),230.0) -> 230 | D31: =IFERROR(SUMIFS('Stock In'!F:F,'Stock In'!C:C,$A31,'Stock In'!D:D,$B31,'Stock In'!E:E,$C31),0) -> 200845 | E31: =IFERROR(SUMIFS(Issues!H:H,Issues!C:C,$A31,Issues!D:D,$B31,Issues!E:E,$C31),0) -> 202400 | F31: =IFERROR(SUMIFS(Returns!H:H,Returns!C:C,$A31,Returns!D:D,$B31,Returns!E:E,$C31),0) -> 29306 | G31: =D31-E31+F31 -> 27751 | H31: =($C31*G31)/1000 -> 6382.73 | I31: =IFERROR( SUMIFS('Stock In'!I:I,'Stock In'!C:C,$A31,'Stock In'!D:D,$B31,'Stock In'!E:E,$C31) / SUMIFS('Stock In'!H:H,'Stock In'!C:C,$A31,'Stock In'!D:D,$B31,'Stock In'!E:E,$C31) , 0) -> 28.102977 | J31: =H31*I31 -> 179373.72
A32: =IFERROR(__xludf.DUMMYFUNCTION("""COMPUTED_VALUE"""),"Chromo") -> Chromo | B32: =IFERROR(__xludf.DUMMYFUNCTION("""COMPUTED_VALUE"""),80.0) -> 80 | C32: =IFERROR(__xludf.DUMMYFUNCTION("""COMPUTED_VALUE"""),260.0) -> 260 | D32: =IFERROR(SUMIFS('Stock In'!F:F,'Stock In'!C:C,$A32,'Stock In'!D:D,$B32,'Stock In'!E:E,$C32),0) -> 35200 | E32: =IFERROR(SUMIFS(Issues!H:H,Issues!C:C,$A32,Issues!D:D,$B32,Issues!E:E,$C32),0) -> 19380 | F32: =IFERROR(SUMIFS(Returns!H:H,Returns!C:C,$A32,Returns!D:D,$B32,Returns!E:E,$C32),0) -> 3000 | G32: =D32-E32+F32 -> 18820 | H32: =($C32*G32)/1000 -> 4893.2 | I32: =IFERROR( SUMIFS('Stock In'!I:I,'Stock In'!C:C,$A32,'Stock In'!D:D,$B32,'Stock In'!E:E,$C32) / SUMIFS('Stock In'!H:H,'Stock In'!C:C,$A32,'Stock In'!D:D,$B32,'Stock In'!E:E,$C32) , 0) -> 26.981889 | J32: =H32*I32 -> 132027.78
A33: =IFERROR(__xludf.DUMMYFUNCTION("""COMPUTED_VALUE"""),"Only ART Paper Without Gumming") -> Only ART Paper Without Gumming | B33: =IFERROR(__xludf.DUMMYFUNCTION("""COMPUTED_VALUE"""),120.0) -> 120 | C33: =IFERROR(__xludf.DUMMYFUNCTION("""COMPUTED_VALUE"""),115.0) -> 115 | D33: =IFERROR(SUMIFS('Stock In'!F:F,'Stock In'!C:C,$A33,'Stock In'!D:D,$B33,'Stock In'!E:E,$C33),0) -> 1250 | E33: =IFERROR(SUMIFS(Issues!H:H,Issues!C:C,$A33,Issues!D:D,$B33,Issues!E:E,$C33),0) -> 0 | F33: =IFERROR(SUMIFS(Returns!H:H,Returns!C:C,$A33,Returns!D:D,$B33,Returns!E:E,$C33),0) -> 0 | G33: =D33-E33+F33 -> 1250 | H33: =($C33*G33)/1000 -> 143.75 | I33: =IFERROR( SUMIFS('Stock In'!I:I,'Stock In'!C:C,$A33,'Stock In'!D:D,$B33,'Stock In'!E:E,$C33) / SUMIFS('Stock In'!H:H,'Stock In'!C:C,$A33,'Stock In'!D:D,$B33,'Stock In'!E:E,$C33) , 0) -> 8.5 | J33: =H33*I33 -> 1221.875
A34: =IFERROR(__xludf.DUMMYFUNCTION("""COMPUTED_VALUE"""),"Chromo") -> Chromo | B34: =IFERROR(__xludf.DUMMYFUNCTION("""COMPUTED_VALUE"""),80.0) -> 80 | C34: =IFERROR(__xludf.DUMMYFUNCTION("""COMPUTED_VALUE"""),126.0) -> 126 | D34: =IFERROR(SUMIFS('Stock In'!F:F,'Stock In'!C:C,$A34,'Stock In'!D:D,$B34,'Stock In'!E:E,$C34),0) -> 8750 | E34: =IFERROR(SUMIFS(Issues!H:H,Issues!C:C,$A34,Issues!D:D,$B34,Issues!E:E,$C34),0) -> 9410 | F34: =IFERROR(SUMIFS(Returns!H:H,Returns!C:C,$A34,Returns!D:D,$B34,Returns!E:E,$C34),0) -> 1980 | G34: =D34-E34+F34 -> 1320 | H34: =($C34*G34)/1000 -> 166.32 | I34: =IFERROR( SUMIFS('Stock In'!I:I,'Stock In'!C:C,$A34,'Stock In'!D:D,$B34,'Stock In'!E:E,$C34) / SUMIFS('Stock In'!H:H,'Stock In'!C:C,$A34,'Stock In'!D:D,$B34,'Stock In'!E:E,$C34) , 0) -> 26.5 | J34: =H34*I34 -> 4407.48
